{"name": "test_006", "status": "failed", "statusDetails": {"message": "AssertionError: assert (1 + 2) == 4", "trace": "def test_006():\n        \"\"\"\n        assert 语句通过断言来触发异常\n        :return:\n        \"\"\"\n        print(\"这是一条异常用例\")\n        a = 1\n        b = 2\n>       assert a + b == 4\nE       assert (1 + 2) == 4\n\ntestcase/test_02.py:17: AssertionError"}, "description": "\n    assert 语句通过断言来触发异常\n    :return:\n    ", "attachments": [{"name": "stdout", "source": "4914ee2e-7a30-48a5-97ba-41e09cf5bc53-attachment.txt", "type": "text/plain"}], "start": 1714034875927, "stop": 1714034875928, "uuid": "0aef3ef6-f1c6-4e37-907b-28abe5509017", "historyId": "eee4592bda3e355b62f15288fb134b69", "testCaseId": "eee4592bda3e355b62f15288fb134b69", "fullName": "testcase.test_02#test_006", "labels": [{"name": "parentSuite", "value": "testcase"}, {"name": "suite", "value": "test_02"}, {"name": "host", "value": "Haiyangxie.local"}, {"name": "thread", "value": "11921-MainThread"}, {"name": "framework", "value": "pytest"}, {"name": "language", "value": "cpython3"}, {"name": "package", "value": "testcase.test_02"}]}